<?php
namespace ChadicusTests\Util;

use Chadicus\Util\Exception;

/**
 * Unit tests for the \Chadicus\Util\Exception class.
 *
 * @coversDefaultClass \Chadicus\Util\Exception
 */
final class ExceptionTest extends \PHPUnit_Framework_TestCase
{
    /**
     * Verify basic functionality of getBaseException().
     *
     * @test
     * @covers ::getBaseException
     *
     * @return void
     */
    public function getBaseException()
    {
        $a = new \ErrorException('exception a');
        $b = new \InvalidArgumentException('exception b', 0, $a);
        $c = new \Exception('exception c', 0, $b);

        $this->assertSame($a, Exception::getBaseException($c));
        $this->assertSame($a, Exception::getBaseException($b));
        $this->assertSame($a, Exception::getBaseException($a));
    }

    /**
     * Verify behavior of getBaseException() when there is no previous exception.
     *
     * @test
     * @covers ::getBaseException
     *
     * @return void
     */
    public function getBaseExceptionNoPrevious()
    {
        $e = new \Exception();
        $this->assertSame($e, Exception::getBaseException($e));
    }

    /**
     * Verifies basic behavior of raise().
     *
     * @test
     * @covers ::raise
     *
     * @return void
     */
    public function raise()
    {
        set_error_handler('\Chadicus\Util\Exception::raise');
        try {
            trigger_error('test', E_USER_NOTICE);
        } catch (\ErrorException $e) {
            $this->assertSame('test', $e->getMessage());
            $this->assertSame(0, $e->getCode());
            $this->assertSame(E_USER_NOTICE, $e->getSeverity());
            $this->assertSame((__LINE__) - 5, $e->getLine());
            $this->assertSame(__FILE__, $e->getFile());
        }

        restore_error_handler();
    }

    /**
     * Verifies raise() returns false when error reporting is disabled.
     *
     * @test
     * @covers ::raise
     *
     * @return void
     */
    public function raiseErrorReportingDisabled()
    {
        $restoreLevel = error_reporting(0);
        $this->assertFalse(Exception::raise(E_USER_NOTICE, 'test', __FILE__, __LINE__));
        error_reporting($restoreLevel);
    }

    /**
     * Verify basic behavior of toArray().
     *
     * @test
     * @covers ::toArray
     *
     * @return void
     */
    public function toArray()
    {
        $expectedLine = __LINE__ + 1;
        $result = Exception::toArray(new \RuntimeException('a message', 21));
        $expected = [
            'type' => 'RuntimeException',
            'message' => 'a message',
            'code' => 21,
            'file' => __FILE__,
            'line' => $expectedLine,
            'trace' => $result['trace'],
            'previous' => null,
        ];

        $this->assertSame($expected, $result);
    }

    /**
     * Verify basic behavior of toArray().
     *
     * @test
     * @covers ::toArray
     *
     * @return void
     */
    public function toArrayWithPrevous()
    {
        $expectedLine = __LINE__ + 1;
        $result = Exception::toArray(new \RuntimeException('a message', 21, new \Exception('a previous', 33)));
        $expected = [
            'type' => 'RuntimeException',
            'message' => 'a message',
            'code' => 21,
            'file' => __FILE__,
            'line' => $expectedLine,
            'trace' => $result['trace'],
            'previous' => [
                'type' => 'Exception',
                'message' => 'a previous',
                'code' => 33,
                'file' => __FILE__,
                'line' => $expectedLine,
                'trace' => $result['previous']['trace'],
                'previous' => null,
            ],
        ];

        $this->assertSame($expected, $result);
    }

    /**
     * Verifies basic behavior of toArray() with a user specified depth.
     *
     * @test
     * @covers ::toArray
     *
     * @return void
     */
    public function toArrayWithDepth()
    {
        $first = new \Exception('first', 11);
        $second = new \Exception('second', 22, $first);
        $third = new \Exception('third', 33, $second);
        $result = Exception::toArray($third, false, 2);

        $expected = [
            'type' => get_class($third),
            'message' => $third->getMessage(),
            'code' => $third->getCode(),
            'file' => $third->getFile(),
            'line' => $third->getLine(),
            'trace' => $third->getTrace(),
            'previous' => [
                'type' => get_class($second),
                'message' => $second->getMessage(),
                'code' => $second->getCode(),
                'file' => $second->getFile(),
                'line' => $second->getLine(),
                'trace' => $second->getTrace(),
                'previous' => null,
            ],
        ];

        $this->assertSame($expected, $result);
    }

    /**
     * Verifies basic behavior of fromLastError().
     *
     * @test
     * @covers ::fromLastError
     *
     * @return void
     */
    public function fromLastError()
    {
        $restoreLevel = error_reporting(0);
        trigger_error('test', E_USER_NOTICE);
        $exception = Exception::fromLastError();
        $this->assertSame('test', $exception->getMessage());
        $this->assertSame(0, $exception->getCode());
        $this->assertSame(E_USER_NOTICE, $exception->getSeverity());
        $this->assertSame((__LINE__) - 5, $exception->getLine());
        $this->assertSame(__FILE__, $exception->getFile());
        error_reporting($restoreLevel);
    }

    /**
     * Verifies behavior of fromLastError() when no error was triggered
     *
     * @test
     * @covers ::fromLastError
     * @runInSeparateProcess
     * @preserveGlobalState disabled
     *
     * @return void
     */
    public function fromLastErrorNoError()
    {
        $this->assertNull(Exception::fromLastError());
    }
}
